Workbook

Sheet Floor Capacity Chart
A1: Floor Capacities per Structural Loading Diagrams (S0.05-S0.08)
A2: Designation | B2: SDL (psf) | C2: LL (psf) | D2: TOTAL CAPACITY (psf)*
A3: 1* | B3: 25 | C3: 40 | D3: =ROUNDDOWN(0.6*1.6/1.3*C3+B3,0) -> 54
A4: 2* | B4: 15 | C4: 100 | D4: =ROUNDDOWN(0.6*1.6/1.3*C4+B4,0) -> 88
A5: 3* | B5: 150 | C5: 20 | D5: =ROUNDDOWN(0.6*1.6/1.3*C5+B5,0) -> 164
A6: 4 | B6: 10 | C6: 150 | D6: =ROUNDDOWN(1.6/1.3*C6+B6,0) -> 194
A7: 5* | B7: 25 | C7: 40 | D7: =ROUNDDOWN(0.6*1.6/1.3*C7+B7,0) -> 54
A8: 6 | B8: 15 | C8: 100 | D8: =ROUNDDOWN(1.6/1.3*C8+B8,0) -> 138
A9: 7 | B9: 10 | C9: 40 | D9: =ROUNDDOWN(1.6/1.3*C9+B9,0) -> 59
A10: 8* | B10: 5 | C10: 100 | D10: =ROUNDDOWN(0.6*1.6/1.3*C10+B10,0) -> 78
A11: 9 | B11: 10 | C11: 125 | D11: =ROUNDDOWN(1.6/1.3*C11+B11,0) -> 163
A12: 10 | B12: 25 | C12: 100 | D12: =ROUNDDOWN(1.6/1.3*C12+B12,0) -> 148
A13: 11 | B13: 15 | C13: 1700 | D13: =ROUNDDOWN(1.6/1.3*C13+B13,0) -> 2107
A14: 12 | B14: 340 | C14: 50 | D14: =ROUNDDOWN(1.6/1.3*C14+B14,0) -> 401
A15: 13 | B15: 10 | C15: 125 | D15: =ROUNDDOWN(1.6/1.3*C15+B15,0) -> 163
A16: 14* | B16: 15 | C16: 100 | D16: =ROUNDDOWN(0.6*1.6/1.3*C16+B16,0) -> 88
A17: 15* | B17: 10 | C17: 100 | D17: =ROUNDDOWN(0.6*1.6/1.3*C17+B17,0) -> 83
A18: 16* | B18: 25 | C18: 100 | D18: =ROUNDDOWN(0.6*1.6/1.3*C18+B18,0) -> 98
A19: 17* | B19: 10 | C19: 20 | D19: =ROUNDDOWN(0.6*1.6/1.3*C19+B19,0) -> 24
A20: 18* | B20: 15 | C20: 50 | D20: =ROUNDDOWN(0.6*1.6/1.3*C20+B20,0) -> 51
A21: 19 | B21: 5 | C21: 150 | D21: =ROUNDDOWN(1.6/1.3*C21+B21,0) -> 189
A22: 20 | B22: 110 | C22: 100 | D22: =ROUNDDOWN(1.6/1.3*C22+B22,0) -> 233
A23: 21 | B23: 220 | C23: 100 | D23: =ROUNDDOWN(1.6/1.3*C23+B23,0) -> 343
A24: 22 | B24: 440 | C24: 100 | D24: =ROUNDDOWN(1.6/1.3*C24+B24,0) -> 563
A25: 23 | B25: 130 | C25: 100 | D25: =ROUNDDOWN(1.6/1.3*C25+B25,0) -> 253
A26: 25 | B26: 175 | C26: 60 | D26: =ROUNDDOWN(1.6/1.3*C26+B26,0) -> 248
A27: 26 | B27: 300 | C27: 60 | D27: =ROUNDDOWN(1.6/1.3*C27+B27,0) -> 373
A28: 31* | B28: 25 | C28: 100 | D28: =ROUNDDOWN(0.6*1.6/1.3*C28+B28,0) -> 98
A29: 32* | B29: 25 | C29: 60 | D29: =ROUNDDOWN(0.6*1.6/1.3*C29+B29,0) -> 69
A30: *Indicates Reducible Live Loads
A31: *Total Capacity =(1.6/1.3 x LL) + SDL, 0.6x(1.6/1.3 x LL) + SDL for reducible loads

Sheet Machine Room Roof Placement
A1: Tower Slab Overview Machine Room | F1: Tower 7 1/2" Slab Placement Reshore (9'-1" Shore Height)
A2: Slab Capacity (psf)* = | B2: ='Floor Capacity Chart'!D6 -> 194 | C2: *#4 Per Floor Capacity Chart | F2: Placement Load (psf) | G2: Reshore Level | H2: Reshore Level Capacity (psf) | I2: Resultant Floor Load | J2: Reshore Type | K2: Reshore Capacity | L2: SF/Shore | M2: Reshore Pattern
A3: Shore Height | B3: Shore Type | C3: Shore Capacity (lbs) | F3: =C14 -> 124 | G3: Machine Room | H3: =$B$2 -> 194 | I3: =F3-H3 -> -70 | J3: 6-6 Ellis Shore | K3: =C$4 -> 5400 | L3: =ROUNDDOWN(K3/I3,0) -> -77 | M3: =IF(AND(L3>24,L3<32),"4x6",IF(AND(L3>32,L3<36),"4x8",IF(AND(L3>36,L3<48),"6x6",IF(AND(L3>48,L3<60),"6x8",IF(AND(L3>60,L3<64),"6x10",IF(AND(L3>64,L3<80),"8x8",IF(AND(L3>80,L3<100),"8x10",IF(L3>100,"10x10","Not Needed")))))))) -> Not Needed
A4: 7'-10" | B4: 6-6 Ellis Shore | C4: 5400 | F4: =I3 -> -70 | G4: Roof | H4: 194 | I4: =F4-H4 -> -264 | J4: #4 Post Shore | K4: 7200 | L4: =ROUNDDOWN(K4/I4,0) -> -27 | M4: =IF(AND(L4>24,L4<32),"4x6",IF(AND(L4>32,L4<36),"4x8",IF(AND(L4>36,L4<48),"6x6",IF(AND(L4>48,L4<60),"6x8",IF(AND(L4>60,L4<64),"6x10",IF(AND(L4>64,L4<80),"8x8",IF(AND(L4>80,L4<100),"8x10",IF(L4>100,"10x10","Not Needed")))))))) -> Not Needed
A12: TOWER TYPICAL SLAB LOADS (L6-38)
A13: Slab Thickness (in) | B13: Construction DL (PSF) | C13: Total Load (psf)*
A14: 7.5 | B14: 30 | C14: =ROUNDUP(A14/12*150+B14,0) -> 124
A15: *Total Load =(Slab Thickness / 12 x 150psf) + DL | F15: Machine Room Roof 7.5" Slab (124 psf)
F22: Machine Room (194 psf capacity)
G24: 155PSF-194PSF = -39PSF
E25: 7'-10" SHORE HEIGHT | G25: 5400#/70PSF
G26: 77SF/SHORE
G27: 8X8 PATTERN
F29: Roof (194 psf capacity)
E32: 11'-10 1/2" SHORE HEIGHT
F36: L38 (54 psf capacity)

Sheet Machine Room Placement
A1: Tower Slab Overview Roof | F1: Tower 7 1/2" Slab Placement Reshore (9'-1" Shore Height)
A2: Slab Capacity (psf)* = | B2: ='Floor Capacity Chart'!D6 -> 194 | C2: *#4 Per Floor Capacity Chart | F2: Placement Load (psf) | G2: Reshore Level | H2: Reshore Level Capacity (psf) | I2: Resultant Floor Load | J2: Reshore Type | K2: Reshore Capacity | L2: SF/Shore | M2: Reshore Pattern
A3: Shore Height | B3: Shore Type | C3: Shore Capacity (lbs) | F3: =C14 -> 155 | G3: Roof | H3: =$B$2 -> 194 | I3: =F3-H3 -> -39 | J3: #4 Post Shore | K3: =C$4 -> 7200 | L3: =ROUNDDOWN(K3/I3,0) -> -184 | M3: =IF(AND(L3>24,L3<32),"4x6",IF(AND(L3>32,L3<36),"4x8",IF(AND(L3>36,L3<48),"6x6",IF(AND(L3>48,L3<60),"6x8",IF(AND(L3>60,L3<64),"6x10",IF(AND(L3>64,L3<80),"8x8",IF(AND(L3>80,L3<100),"8x10",IF(L3>100,"10x10","Not Needed")))))))) -> Not Needed
A4: 11'-10 1/2" | B4: #4 Post Shore | C4: 7200 | F4: =I3 -> -39 | G4: L38 | H4: ='Floor Capacity Chart'!D7 -> 54 | I4: =F4-H4 -> -93 | J4: #3 Post Shore | K4: 5900 | L4: =ROUNDDOWN(K4/I4,0) -> -63 | M4: =IF(AND(L4>24,L4<32),"4x6",IF(AND(L4>32,L4<36),"4x8",IF(AND(L4>36,L4<48),"6x6",IF(AND(L4>48,L4<60),"6x8",IF(AND(L4>60,L4<64),"6x10",IF(AND(L4>64,L4<80),"8x8",IF(AND(L4>80,L4<100),"8x10",IF(L4>100,"10x10","Not Needed")))))))) -> Not Needed
A12: TOWER TYPICAL SLAB LOADS (L6-38)
A13: Slab Thickness (in) | B13: Construction DL (PSF) | C13: Total Load (psf)*
A14: 10 | B14: 30 | C14: =ROUNDUP(A14/12*150+B14,0) -> 155
A15: *Total Load =(Slab Thickness / 12 x 150psf) + DL | F15: Machine Room 10" Slab (155 psf)
F22: Roof (194 psf capacity)
E25: 11'-10 1/2 " SHORE HEIGHT
F29: L38 (54 psf capacity)
E32: 10'-1" SHORE HEIGHT
F36: SF-3 (54 psf capacity) (L6-35)

Sheet Roof Placement 10in Slab
A1: Tower Slab Overview L38 | F1: Tower 7 1/2" Slab Placement Reshore (9'-1" Shore Height)
A2: Slab Capacity (psf)* = | B2: ='Floor Capacity Chart'!D7 -> 54 | C2: *#5 Per Floor Capacity Chart | F2: Placement Load (psf) | G2: Reshore Level | H2: Reshore Level Capacity (psf) | I2: Resultant Floor Load | J2: Reshore Type | K2: Reshore Capacity | L2: SF/Shore | M2: Reshore Pattern
A3: Shore Height | B3: Shore Type | C3: Shore Capacity (lbs) | F3: =C14 -> 155 | G3: SF-1 | H3: =$B$2 -> 54 | I3: =F3-H3 -> 101 | J3: 6-6 Ellis Shore | K3: 5400 | L3: =ROUNDDOWN(K3/I3,0) -> 53 | M3: =IF(AND(L3>24,L3<32),"4x6",IF(AND(L3>32,L3<36),"4x8",IF(AND(L3>36,L3<48),"6x6",IF(AND(L3>48,L3<60),"6x8",IF(AND(L3>60,L3<64),"6x10",IF(AND(L3>64,L3<80),"8x8",IF(AND(L3>80,L3<100),"8x10",IF(L3>100,"10x10","Not Needed")))))))) -> 6x8
A4: 10'-1" | B4: #3 Post Shore | C4: 5900 | F4: =I3 -> 101 | G4: SF-2 | H4: =B2 -> 54 | I4: =F4-H4 -> 47 | J4: 6-6 Ellis Shore | K4: 5400 | L4: =ROUNDDOWN(K4/I4,0) -> 114 | M4: =IF(AND(L4>24,L4<32),"4x6",IF(AND(L4>32,L4<36),"4x8",IF(AND(L4>36,L4<48),"6x6",IF(AND(L4>48,L4<60),"6x8",IF(AND(L4>60,L4<64),"6x10",IF(AND(L4>64,L4<80),"8x8",IF(AND(L4>80,L4<100),"8x10",IF(L4>100,"10x10","Not Needed")))))))) -> 10x10
F5: =I4 -> 47 | G5: SF-3 | H5: =H4 -> 54 | I5: =F5-H5 -> -7 | J5: 6-6 Ellis Shore | K5: 5400 | L5: =ROUNDDOWN(K5/I5,0) -> -771 | M5: =IF(AND(L5>24,L5<32),"4x6",IF(AND(L5>32,L5<36),"4x8",IF(AND(L5>36,L5<48),"6x6",IF(AND(L5>48,L5<60),"6x8",IF(AND(L5>60,L5<64),"6x10",IF(AND(L5>64,L5<80),"8x8",IF(AND(L5>80,L5<100),"8x10",IF(L5>100,"10x10","Not Needed")))))))) -> Not Needed
A12: TOWER TYPICAL SLAB LOADS (L6-38)
A13: Slab Thickness (in) | B13: Construction DL (PSF) | C13: Total Load (psf)*
A14: 10 | B14: 30 | C14: =ROUNDUP(A14/12*150+B14,0) -> 155
A15: *Total Load =(Slab Thickness / 12 x 150psf) + DL | F15: Roof 10" Slab (155 psf)
F22: L38 (54 psf capacity)
G24: 155PSF-54PSF = 101PSF
E25: 10'-1" SHORE HEIGHT | G25: 5900#/101PSF
G26: 58SF/SHORE
G27: 6X8 PATTERN
F29: L37 (54 psf capacity)
G31: 101PSF-54PSF = 47PSF
E32: 9'-1" SHORE HEIGHT | G32: 5400#/47PSF
G33: 114SF/SHORE
G34: 10X10 PATTERN
F36: L36 (54 psf capacity)

Sheet Typical Tower Reshore (L8-38)
A1: Tower Slab Overview (L6-38) | F1: Tower 7 1/2" Slab Placement Reshore (9'-1" Shore Height)
A2: Slab Capacity (psf)* = | B2: ='Floor Capacity Chart'!D7 -> 54 | C2: *#5 Per Floor Capacity Chart | F2: Placement Load (psf) | G2: Reshore Level | H2: Reshore Level Capacity (psf) | I2: Resultant Floor Load | J2: Reshore Type | K2: Reshore Capacity | L2: SF/Shore | M2: Reshore Pattern
A3: Shore Height | B3: Shore Type | C3: Shore Capacity (lbs) | F3: =C14 -> 124 | G3: SF-1 | H3: =$B$2 -> 54 | I3: =F3-H3 -> 70 | J3: 6-6 Ellis Shore | K3: =C$4 -> 5400 | L3: =ROUNDDOWN(K3/I3,0) -> 77 | M3: =IF(AND(L3>24,L3<32),"4x6",IF(AND(L3>32,L3<36),"4x8",IF(AND(L3>36,L3<48),"6x6",IF(AND(L3>48,L3<60),"6x8",IF(AND(L3>60,L3<64),"6x10",IF(AND(L3>64,L3<80),"8x8",IF(AND(L3>80,L3<100),"8x10",IF(L3>100,"10x10","Not Needed")))))))) -> 8x8
A4: 9'-1" | B4: 6-6 Ellis Shore | C4: 5400 | F4: =I3 -> 70 | G4: SF-2 | H4: =B2 -> 54 | I4: =F4-H4 -> 16 | J4: 6-6 Ellis Shore | K4: 5400 | L4: =ROUNDDOWN(K4/I4,0) -> 337 | M4: =IF(AND(L4>24,L4<32),"4x6",IF(AND(L4>32,L4<36),"4x8",IF(AND(L4>36,L4<48),"6x6",IF(AND(L4>48,L4<60),"6x8",IF(AND(L4>60,L4<64),"6x10",IF(AND(L4>64,L4<80),"8x8",IF(AND(L4>80,L4<100),"8x10",IF(L4>100,"10x10","Not Needed")))))))) -> 10x10
F5: 16 | G5: SF-3 | H5: =H4 -> 54 | I5: =F5-H5 -> -38 | J5: 6-6 Ellis Shore | K5: 5400 | L5: =ROUNDDOWN(K5/I5,0) -> -142 | M5: =IF(AND(L5>24,L5<32),"4x6",IF(AND(L5>32,L5<36),"4x8",IF(AND(L5>36,L5<48),"6x6",IF(AND(L5>48,L5<60),"6x8",IF(AND(L5>60,L5<64),"6x10",IF(AND(L5>64,L5<80),"8x8",IF(AND(L5>80,L5<100),"8x10",IF(L5>100,"10x10","Not Needed")))))))) -> Not Needed
A12: TOWER TYPICAL SLAB LOADS (L6-38)
A13: Slab Thickness (in) | B13: Construction DL (PSF) | C13: Total Load (psf)*
A14: 7.5 | B14: 30 | C14: =ROUNDUP(A14/12*150+B14,0) -> 124
A15: *Total Load =(Slab Thickness / 12 x 150psf) + DL | F15: TOWER 7 1/2" Slab (124 psf) (L9-38)
F22: SF-1 (54 psf capacity)
G24: 124PSF-54PSF = 70PSF
E25: 9'-1" SHORE HEIGHT | G25: 5400#/70PSF
G26: 77SF/SHORE
G27: 8X8 PATTERN
F29: SF-2 (54 psf capacity)
G31: 70PSF-54PSF = 16PSF
E32: 9'-1" SHORE HEIGHT | G32: 5400#/16PSF
G33: 337SF/SHORE
G34: 10X10 PATTERN
F36: SF-3 (54 psf capacity) (L6-35)

Sheet L8 Placement
A1: L7 Slab Overview | F1: L8 7 1/2" Slab Placement Reshore (9'-1" Shore Height)
A2: Slab Capacity (psf)* = | B2: ='Floor Capacity Chart'!D7 -> 54 | C2: *#5 Per Floor Capacity Chart | F2: Placement Load (psf) | G2: Reshore Level | H2: Reshore Level Capacity (psf) | I2: Resultant Floor Load | J2: Reshore Type | K2: Reshore Capacity | L2: SF/Shore | M2: Reshore Pattern
A3: Shore Height | B3: Shore Type | C3: Shore Capacity (lbs) | F3: =C14 -> 124 | G3: L7 | H3: =$B$2 -> 54 | I3: =F3-H3 -> 70 | J3: 6-6 Ellis Shore | K3: =C$4 -> 5400 | L3: =ROUNDDOWN(K3/I3,0) -> 77 | M3: =IF(AND(L3>24,L3<32),"4x6",IF(AND(L3>32,L3<36),"4x8",IF(AND(L3>36,L3<48),"6x6",IF(AND(L3>48,L3<60),"6x8",IF(AND(L3>60,L3<64),"6x10",IF(AND(L3>64,L3<80),"8x8",IF(AND(L3>80,L3<100),"8x10",IF(L3>100,"10x10","Not Needed")))))))) -> 8x8
A4: 9'-1" | B4: 6-6 Ellis Shore | C4: 5400 | F4: =I3 -> 70 | G4: L6 | H4: =B2 -> 54 | I4: =F4-H4 -> 16 | J4: #5 HV Shore | K4: 7916 | L4: =ROUNDDOWN(K4/I4,0) -> 494 | M4: =IF(AND(L4>24,L4<32),"4x6",IF(AND(L4>32,L4<36),"4x8",IF(AND(L4>36,L4<48),"6x6",IF(AND(L4>48,L4<60),"6x8",IF(AND(L4>60,L4<64),"6x10",IF(AND(L4>64,L4<80),"8x8",IF(AND(L4>80,L4<100),"8x10",IF(L4>100,"10x10","Not Needed")))))))) -> 10x10
F5: 16 | G5: L5 | H5: 88 | I5: =F5-H5 -> -72 | M5: =IF(AND(L5>24,L5<32),"4x6",IF(AND(L5>32,L5<36),"4x8",IF(AND(L5>36,L5<48),"6x6",IF(AND(L5>48,L5<60),"6x8",IF(AND(L5>60,L5<64),"6x10",IF(AND(L5>64,L5<80),"8x8",IF(AND(L5>80,L5<100),"8x10",IF(L5>100,"10x10","Not Needed")))))))) -> Not Needed
A12: L8 TYPICAL SLAB LOADS
A13: Slab Thickness (in) | B13: Construction DL (PSF) | C13: Total Load (psf)*
A14: 7.5 | B14: 30 | C14: =ROUNDUP(A14/12*150+B14,0) -> 124
A15: *Total Load =(Slab Thickness / 12 x 150psf) + DL | F15: L8 7 1/2" Slab (124 psf)
F22: L7 (54 psf capacity)
G24: 124PSF-54PSF = 70PSF
E25: 9'-1" SHORE HEIGHT | G25: 5400#/70PSF
G26: 77SF/SHORE
G27: 8X8 PATTERN
F29: L6 (54 psf capacity)
G31: 70PSF-54PSF = 16PSF
E32: 14'-4 1/2" SHORE HEIGHT | G32: 7916#/16PSF
G33: 494SF/SHORE
G34: 10X10 PATTERN
F36: L5 (88 psf capacity)

Sheet L7 Placement
A1: L6 Slab Overview | F1: Tower 7 1/2" Slab Placement Reshore (9'-1" Shore Height)
A2: Slab Capacity (psf)* = | B2: ='Floor Capacity Chart'!D7 -> 54 | C2: *#5 Per Floor Capacity Chart | F2: Placement Load (psf) | G2: Reshore Level | H2: Reshore Level Capacity (psf) | I2: Resultant Floor Load | J2: Reshore Type | K2: Reshore Capacity | L2: SF/Shore | M2: Reshore Pattern
A3: Shore Height | B3: Shore Type | C3: Shore Capacity (lbs) | F3: =C14 -> 124 | G3: L6 | H3: =$B$2 -> 54 | I3: =F3-H3 -> 70 | J3: #5 HV Shore | K3: =C$4 -> 7916 | L3: =ROUNDDOWN(K3/I3,0) -> 113 | M3: =IF(AND(L3>24,L3<32),"4x6",IF(AND(L3>32,L3<36),"4x8",IF(AND(L3>36,L3<48),"6x6",IF(AND(L3>48,L3<60),"6x8",IF(AND(L3>60,L3<64),"6x10",IF(AND(L3>64,L3<80),"8x8",IF(AND(L3>80,L3<100),"8x10",IF(L3>100,"10x10","Not Needed")))))))) -> 10x10
A4: 14'-6 1/2" | B4: HV #5 Shore | C4: 7916 | F4: =I3 -> 70 | G4: L5 | H4: 88 | I4: =F4-H4 -> -18 | J4: #5 HV Shore | K4: 8166 | L4: =ROUNDDOWN(K4/I4,0) -> -453 | M4: =IF(AND(L4>24,L4<32),"4x6",IF(AND(L4>32,L4<36),"4x8",IF(AND(L4>36,L4<48),"6x6",IF(AND(L4>48,L4<60),"6x8",IF(AND(L4>60,L4<64),"6x10",IF(AND(L4>64,L4<80),"8x8",IF(AND(L4>80,L4<100),"8x10",IF(L4>100,"10x10","Not Needed")))))))) -> Not Needed
F5: =I4 -> -18 | G5: L4 | H5: 59 | I5: =F5-H5 -> -77 | M5: =IF(AND(L5>24,L5<32),"4x6",IF(AND(L5>32,L5<36),"4x8",IF(AND(L5>36,L5<48),"6x6",IF(AND(L5>48,L5<60),"6x8",IF(AND(L5>60,L5<64),"6x10",IF(AND(L5>64,L5<80),"8x8",IF(AND(L5>80,L5<100),"8x10",IF(L5>100,"10x10","Not Needed")))))))) -> Not Needed
A12: L7 TYPICAL SLAB LOADS
A13: Slab Thickness (in) | B13: Construction DL (PSF) | C13: Total Load (psf)*
A14: 7.5 | B14: 30 | C14: =ROUNDUP(A14/12*150+B14,0) -> 124
A15: *Total Load =(Slab Thickness / 12 x 150psf) + DL | F15: L7 7 1/2" Slab (124 psf)
F22: L6 (54 psf capacity)
G24: 124PSF-54PSF = 70PSF
E25: 14'-4 1/2" SHORE HEIGHT | G25: 7916#/70PSF
G26: 113SF/SHORE
G27: 10x10 PATTERN
F29: L5 (88psf capacity)
G31: 70PSF-88PSF = -18PSF
E32: 13'-6 1/2" SHORE HEIGHT | G32: RESHORE NOT NEEDED
G33: 10X10 PATTERN
F36: L4 (59 psf capacity)

Sheet L6 Placement
A1: L5 Slab Overview | F1: L6 - 7 1/2" Slab Placement Reshore (9'-1" Shore Height)
A2: Slab Capacity (psf)* = | B2: 69 | C2: *#5 Per Floor Capacity Chart | F2: Placement Load (psf) | G2: Reshore Level | H2: Reshore Level Capacity (psf) | I2: Resultant Floor Load | J2: Reshore Type | K2: Reshore Capacity | L2: SF/Shore | M2: Reshore Pattern
A3: Shore Height | B3: Shore Type | C3: Shore Capacity (lbs) | F3: =C14 -> 124 | G3: L5 | H3: 69 | I3: =F3-H3 -> 55 | J3: #5 HV Shore | K3: =C$4 -> 8333 | L3: =ROUNDDOWN(K3/I3,0) -> 151 | M3: =IF(AND(L3>24,L3<32),"4x6",IF(AND(L3>32,L3<36),"4x8",IF(AND(L3>36,L3<48),"6x6",IF(AND(L3>48,L3<60),"6x8",IF(AND(L3>60,L3<64),"6x10",IF(AND(L3>64,L3<80),"8x8",IF(AND(L3>80,L3<100),"8x10",IF(L3>100,"10x10","Not Needed")))))))) -> 10x10
A4: 13'-4" | B4: HV #5 Shore | C4: 8333 | F4: =I3 -> 55 | G4: L4 | H4: 59 | I4: =F4-H4 -> -4 | J4: 6-6 Ellis Shore | K4: 5400 | L4: =ROUNDDOWN(K4/I4,0) -> -1350 | M4: =IF(AND(L4>24,L4<32),"4x6",IF(AND(L4>32,L4<36),"4x8",IF(AND(L4>36,L4<48),"6x6",IF(AND(L4>48,L4<60),"6x8",IF(AND(L4>60,L4<64),"6x10",IF(AND(L4>64,L4<80),"8x8",IF(AND(L4>80,L4<100),"8x10",IF(L4>100,"10x10","Not Needed")))))))) -> Not Needed
F9: L6 BEAM LOADS | K9: Beam Reshore Spacing
F10: Beam Width (in) | G10: Beam Depth (in) | H10: Surrounding Slab Depth (in) | I10: Beam Load (plf)* | K10: HV#5 Spacing | L10: 6-6 Ellis Spacing (ft)
F11: 78 | G11: 60 | H11: 7.5 | I11: =ROUNDUP((G11-H11)/12*150*F11/12,0) -> 4266 | K11: =C4/I11 -> 1.9533521 | L11: =4635/I11 -> 1.0864979
A12: L6 TYPICAL SLAB LOADS
A13: Slab Thickness (in) | B13: Construction DL (PSF) | C13: Total Load (psf)*
A14: 7.5 | B14: 30 | C14: =ROUNDUP(A14/12*150+B14,0) -> 124
A15: *Total Load =(Slab Thickness / 12 x 150psf) + DL | F15: L6 7 1/2" Slab (124 psf)
F22: L5 (69 psf capacity)
G24: 124PSF-69PSF = 55PSF
E25: 13'-4" SHORE HEIGHT | G25: 8333#/55PSF
G26: 231SF/SHORE
G27: 10X10 PATTERN
F29: L4 (59psf capacity)
G31: 55PSF-59PSF = -4PSF
E32: 8'-6 1/2" SHORE HEIGHT | G32: RESHORE NOT NEEDED
G33: 10X10 PATTERN
F36: L3 (59 psf capacity)

Sheet L5 Placement
A1: L4 Overview | H1: L5 8" Slab Placement Reshore (8'-6 1/2" Shore Height)
A2: Slab Capacity (psf)* = | B2: ='Floor Capacity Chart'!D9 -> 59 | C2: *#7 Per Floor Capacity Chart | H2: Placement Load (psf) | I2: Reshore Level | J2: Reshore Level Capacity (psf) | K2: Resultant Floor Load | L2: Reshore Type | M2: Reshore Capacity | N2: SF/Shore | O2: Reshore Pattern
A3: Shore Height | B3: Shore Type | C3: Shore Capacity (lbs) | H3: =C14 -> 130 | I3: L4 | J3: =$B$2 -> 59 | K3: =H3-J3 -> 71 | L3: 6-6 Ellis Shore | M3: =C4 -> 5400 | N3: =ROUNDDOWN(M3/K3,0) -> 76 | O3: =IF(AND(N3>24,N3<32),"4x6",IF(AND(N3>32,N3<36),"4x8",IF(AND(N3>36,N3<48),"6x6",IF(AND(N3>48,N3<60),"6x8",IF(AND(N3>60,N3<64),"6x10",IF(AND(N3>64,N3<80),"8x8",IF(AND(N3>80,N3<100),"8x10",IF(N3>100,"10x10","Not Needed")))))))) -> 8x8
A4: 8'-6 1/2" | B4: 6-6 Ellis Shore | C4: 5400 | H4: =K3 -> 71 | I4: L3 | J4: 59 | K4: =H4-J4 -> 12 | L4: 6-6 Ellis Shore | M4: 5400 | N4: =ROUNDDOWN(M4/K4,0) -> 450 | O4: =IF(AND(N4>24,N4<32),"4x6",IF(AND(N4>32,N4<36),"4x8",IF(AND(N4>36,N4<48),"6x6",IF(AND(N4>48,N4<60),"6x8",IF(AND(N4>60,N4<64),"6x10",IF(AND(N4>64,N4<80),"8x8",IF(AND(N4>80,N4<100),"8x10",IF(N4>100,"10x10","Not Needed")))))))) -> 10x10
H5: =K4 -> 12 | I5: L2 | J5: 59 | K5: =H5-J5 -> -47 | L5: 6-8 Ellis Shore | M5: 4635 | N5: =ROUNDDOWN(M5/K5,0) -> -98 | O5: =IF(AND(N5>24,N5<32),"4x6",IF(AND(N5>32,N5<36),"4x8",IF(AND(N5>36,N5<48),"6x6",IF(AND(N5>48,N5<60),"6x8",IF(AND(N5>60,N5<64),"6x10",IF(AND(N5>64,N5<80),"8x8",IF(AND(N5>80,N5<100),"8x10",IF(N5>100,"10x10","Not Needed")))))))) -> Not Needed
H11: L5 10" Slab Placement Reshore (8'-6 1/2" Shore Height)
A12: L5 TYPICAL SLAB LOADS | H12: Placement Load (psf) | I12: Reshore Level | J12: Reshore Level Capacity (psf) | K12: Resultant Floor Load | L12: Reshore Type | M12: Reshore Capacity | N12: SF/Shore | O12: Reshore Pattern
A13: Slab Thickness (in) | B13: Construction DL (PSF) | C13: Total Load (psf)* | H13: 155 | I13: L4 | J13: =$B$2 -> 59 | K13: =H13-J13 -> 96 | L13: 6-6 Ellis Shore | M13: 5400 | N13: =ROUNDDOWN(M13/K13,0) -> 56 | O13: =IF(AND(N13>24,N13<32),"4x6",IF(AND(N13>32,N13<36),"4x8",IF(AND(N13>36,N13<48),"6x6",IF(AND(N13>48,N13<60),"6x8",IF(AND(N13>60,N13<64),"6x10",IF(AND(N13>64,N13<80),"8x8",IF(AND(N13>80,N13<100),"8x10",IF(N13>100,"10x10","Not Needed")))))))) -> 6x8
A14: 8 | B14: 30 | C14: =ROUNDUP(A14/12*150+B14,0) -> 130 | H14: =K13 -> 96 | I14: L3 | J14: 59 | K14: =H14-J14 -> 37 | L14: 6-6 Ellis Shore | M14: 5400 | N14: =ROUNDDOWN(M14/K14,0) -> 145 | O14: =IF(AND(N14>24,N14<32),"4x6",IF(AND(N14>32,N14<36),"4x8",IF(AND(N14>36,N14<48),"6x6",IF(AND(N14>48,N14<60),"6x8",IF(AND(N14>60,N14<64),"6x10",IF(AND(N14>64,N14<80),"8x8",IF(AND(N14>80,N14<100),"8x10",IF(N14>100,"10x10","Not Needed")))))))) -> 10x10
A15: 10 | B15: 30 | C15: =ROUNDUP(A15/12*150+B15,0) -> 155 | H15: =K14 -> 37 | I15: L2 | J15: 59 | K15: =H15-J15 -> -22 | L15: 6-8 Ellis Shore | M15: 4635 | N15: =ROUNDDOWN(M15/K15,0) -> -210 | O15: =IF(AND(N15>24,N15<32),"4x6",IF(AND(N15>32,N15<36),"4x8",IF(AND(N15>36,N15<48),"6x6",IF(AND(N15>48,N15<60),"6x8",IF(AND(N15>60,N15<64),"6x10",IF(AND(N15>64,N15<80),"8x8",IF(AND(N15>80,N15<100),"8x10",IF(N15>100,"10x10","Not Needed")))))))) -> Not Needed
A16: *Total Load =(Slab Thickness / 12 x 150psf) + DL
A19: L5 BEAM LOADS | F19: Beam Reshore Spacing
A20: Beam Width (in) | B20: Beam Depth (in) | C20: Surrounding Slab Depth (in) | D20: Beam Load (plf)* | F20: 6-6 Ellis Spacing (ft) | G20: 6-8 Ellis Spacing (ft)
A21: 48 | B21: 64 | C21: 8 | D21: =ROUNDUP((B21-C21)/12*150*A21/12,0) -> 2800 | F21: =C$4/$D21 -> 1.9285714 | G21: =4635/$D21 -> 1.6553571
A22: 36 | B22: 65 | C22: 8 | D22: =ROUNDUP((B22-C22)/12*150*A22/12,0) -> 2138 | F22: =C$4/$D22 -> 2.525725 | G22: =4635/$D22 -> 2.1679139 | J22: L5 8" Slab (130 psf)
A23: 38 | B23: 68 | C23: 8 | D23: =ROUNDUP((B23-C23)/12*150*A23/12,0) -> 2375 | F23: =C$4/$D23 -> 2.2736842 | G23: =4635/$D23 -> 1.9515789
A24: 72 | B24: 72 | C24: 8 | D24: =ROUNDUP((B24-C24)/12*150*A24/12,0) -> 4800 | F24: =C$4/$D24 -> 1.125 | G24: =4635/$D24 -> 0.965625
A25: 144 | B25: 82 | C25: 8 | D25: =ROUNDUP((B25-C25)/12*150*A25/12,0) -> 11100 | F25: =C$4/$D25 -> 0.48648649 | G25: =4635/$D25 -> 0.41756757
J29: L4 (59 psf capacity)
A31: *Beam Load = (Beam Depth - Surrounding Slab Depth) / 12 x 150psf x (Beam Width / 12) | K31: 130PSF-59PSF = 71PSF
I32: 8'-6 1/2" SHORE HEIGHT | K32: 5400#/71PSF
K33: 76SF/SHORE
K34: 8x8 PATTERN
J36: L3 (59psf capacity)
K38: 71PSF-59PSF = 12PSF
I39: 8'-6 1/2" SHORE HEIGHT | K39: 5400#/12PSF
K40: 450SF/SHORE
K41: 10X10 PATTERN
J43: L2 (59 psf capacity)
K45: RESHORE NOT NEEDED
I46: 10'-10 1/2" SHORE HEIGHT
J50: L1 SOG
J54: L5 10" Slab (155 psf)
J61: L4 (59 psf capacity)
K63: 155PSF-59PSF = 96PSF
I64: 8'-6 1/2" SHORE HEIGHT | K64: 5400#/96PSF
K65: 56SF/SHORE
K66: 6X8 PATTERN
J68: L3 (59psf capacity)
K70: 96PSF-59PSF = 37PSF
...

Sheet L4.5 Placement
A1: L4 Overview | H1: L4.5 10" Slab Placement Reshore (8'-6 1/2" Shore Height)
A2: Slab Capacity (psf)* = | B2: ='Floor Capacity Chart'!D9 -> 59 | C2: *#7 Per Floor Capacity Chart | H2: Placement Load (psf) | I2: Reshore Level | J2: Reshore Level Capacity (psf) | K2: Resultant Floor Load | L2: Reshore Type | M2: Reshore Capacity | N2: SF/Shore | O2: Reshore Pattern
A3: Shore Height | B3: Shore Type | C3: Shore Capacity (lbs) | H3: =C14 -> 155 | I3: L4 | J3: =$B$2 -> 59 | K3: =H3-J3 -> 96 | L3: 6-6 Ellis Shore | M3: =C4 -> 5400 | N3: =ROUNDDOWN(M3/K3,0) -> 56 | O3: =IF(AND(N3>24,N3<32),"4x6",IF(AND(N3>32,N3<36),"4x8",IF(AND(N3>36,N3<48),"6x6",IF(AND(N3>48,N3<60),"6x8",IF(AND(N3>60,N3<64),"6x10",IF(AND(N3>64,N3<80),"8x8",IF(AND(N3>80,N3<100),"8x10",IF(N3>100,"10x10","Not Needed")))))))) -> 6x8
A4: 8'-6 1/2" | B4: 6-6 Ellis Shore | C4: 5400 | H4: =K3 -> 96 | I4: L3 | J4: 59 | K4: =H4-J4 -> 37 | L4: 6-6 Ellis Shore | M4: 5400 | N4: =ROUNDDOWN(M4/K4,0) -> 145 | O4: =IF(AND(N4>24,N4<32),"4x6",IF(AND(N4>32,N4<36),"4x8",IF(AND(N4>36,N4<48),"6x6",IF(AND(N4>48,N4<60),"6x8",IF(AND(N4>60,N4<64),"6x10",IF(AND(N4>64,N4<80),"8x8",IF(AND(N4>80,N4<100),"8x10",IF(N4>100,"10x10","Not Needed")))))))) -> 10x10
H5: =K4 -> 37 | I5: L2 | J5: 59 | K5: =H5-J5 -> -22 | L5: 6-8 Ellis Shore | M5: 4635 | N5: =ROUNDDOWN(M5/K5,0) -> -210 | O5: =IF(AND(N5>24,N5<32),"4x6",IF(AND(N5>32,N5<36),"4x8",IF(AND(N5>36,N5<48),"6x6",IF(AND(N5>48,N5<60),"6x8",IF(AND(N5>60,N5<64),"6x10",IF(AND(N5>64,N5<80),"8x8",IF(AND(N5>80,N5<100),"8x10",IF(N5>100,"10x10","Not Needed")))))))) -> Not Needed
H11: L4.5 12" Slab Placement Reshore (8'-6 1/2" Shore Height)
A12: L4.5 TYPICAL SLAB LOADS | H12: Placement Load (psf) | I12: Reshore Level | J12: Reshore Level Capacity (psf) | K12: Resultant Floor Load | L12: Reshore Type | M12: Reshore Capacity | N12: SF/Shore | O12: Reshore Pattern
A13: Slab Thickness (in) | B13: Construction DL (PSF) | C13: Total Load (psf)* | H13: =C15 -> 180 | I13: L4 | J13: =$B$2 -> 59 | K13: =H13-J13 -> 121 | L13: 6-6 Ellis Shore | M13: 5400 | N13: =ROUNDDOWN(M13/K13,0) -> 44 | O13: =IF(AND(N13>24,N13<32),"4x6",IF(AND(N13>32,N13<36),"4x8",IF(AND(N13>36,N13<48),"6x6",IF(AND(N13>48,N13<60),"6x8",IF(AND(N13>60,N13<64),"6x10",IF(AND(N13>64,N13<80),"8x8",IF(AND(N13>80,N13<100),"8x10",IF(N13>100,"10x10","Not Needed")))))))) -> 6x6
A14: 10 | B14: 30 | C14: =ROUNDUP(A14/12*150+B14,0) -> 155 | H14: =K13 -> 121 | I14: L3 | J14: 59 | K14: =H14-J14 -> 62 | L14: 6-6 Ellis Shore | M14: 5400 | N14: =ROUNDDOWN(M14/K14,0) -> 87 | O14: =IF(AND(N14>24,N14<32),"4x6",IF(AND(N14>32,N14<36),"4x8",IF(AND(N14>36,N14<48),"6x6",IF(AND(N14>48,N14<60),"6x8",IF(AND(N14>60,N14<64),"6x10",IF(AND(N14>64,N14<80),"8x8",IF(AND(N14>80,N14<100),"8x10",IF(N14>100,"10x10","Not Needed")))))))) -> 8x10
A15: 12 | B15: 30 | C15: =ROUNDUP(A15/12*150+B15,0) -> 180 | H15: =K14 -> 62 | I15: L2 | J15: 59 | K15: =H15-J15 -> 3 | L15: 6-8 Ellis Shore | M15: 4635 | N15: =ROUNDDOWN(M15/K15,0) -> 1545 | O15: =IF(AND(N15>24,N15<32),"4x6",IF(AND(N15>32,N15<36),"4x8",IF(AND(N15>36,N15<48),"6x6",IF(AND(N15>48,N15<60),"6x8",IF(AND(N15>60,N15<64),"6x10",IF(AND(N15>64,N15<80),"8x8",IF(AND(N15>80,N15<100),"8x10",IF(N15>100,"10x10","Not Needed")))))))) -> 10x10
A16: *Total Load =(Slab Thickness / 12 x 150psf) + DL
A19: L4.5 BEAM LOADS | F19: Beam Reshore Spacing
A20: Beam Width (in) | B20: Beam Depth (in) | C20: Surrounding Slab Depth (in) | D20: Beam Load (plf)* | F20: 6-6 Ellis Spacing (ft) 5400# | G20: 6-8 Ellis Spacing (ft) 4635# w/ rem capacity* | H20: 625 Spacing (ft) 7250# w/ rem capacity* | I20: *22PSF x 8ft Trib 176plf
A21: 48 | B21: 64 | C21: 10 | D21: =ROUNDUP((B21-C21)/12*150*A21/12,0) -> 2700 | F21: =C$4/$D21 -> 2 | G21: =4635/($D21-22*8) -> 1.8363708 | H21: =7250/(D21-22*8) -> 2.8724247
A22: 36 | B22: 65 | C22: 10 | D22: =ROUNDUP((B22-C22)/12*150*A22/12,0) -> 2063 | F22: =C$4/$D22 -> 2.6175473 | G22: =4635/($D22-22*8) -> 2.4562798 | H22: =7250/(D22-22*8) -> 3.8420774 | K22: L4.5 10" Slab (155psf)
A23: 38 | B23: 68 | C23: 10 | D23: =ROUNDUP((B23-C23)/12*150*A23/12,0) -> 2296 | F23: =C$4/$D23 -> 2.3519164 | G23: =4635/($D23-22*8) -> 2.1863208 | H23: =7250/(D23-22*8) -> 3.4198113
A24: 72 | B24: 72 | C24: 10 | D24: =ROUNDUP((B24-C24)/12*150*A24/12,0) -> 4650 | F24: =C$4/$D24 -> 1.1612903 | G24: =4635/($D24-22*8) -> 1.0359857 | H24: =7250/(D24-22*8) -> 1.6204738
A25: 144 | B25: 82 | C25: 10 | D25: =ROUNDUP((B25-C25)/12*150*A25/12,0) -> 10800 | F25: =C$4/$D25 -> 0.5 | G25: =4635/($D25-22*8) -> 0.43627636 | H25: =7250/(D25-22*8) -> 0.68241717
A26: 90 | B26: 18 | C26: 10 | D26: =ROUNDUP((B26-C26)/12*150*A26/12,0) -> 750 | F26: =ROUNDDOWN(C$4/$D26,1) -> 7.2 | G26: =4635/($D26-22*8) -> 8.0749129 | H26: =7250/(D26-22*8) -> 12.630662
A27: 90 | B27: 21.25 | C27: 10 | D27: =ROUNDUP((B27-C27)/12*150*A27/12,0) -> 1055 | F27: =ROUNDDOWN(C$4/$D27,1) -> 5.1 | G27: =4635/($D27-22*8) -> 5.2730375 | H27: =7250/(D27-22*8) -> 8.2480091
A28: 66 | B28: 18 | C28: 10 | D28: =ROUNDUP((B28-C28)/12*150*A28/12,0) -> 550 | F28: =ROUNDDOWN(C$4/$D28,1) -> 9.8 | G28: =4635/($D28-22*8) -> 12.393048 | H28: =7250/(D28-22*8) -> 19.385027
A29: 12 | B29: 67 | C29: 10 | D29: =ROUNDUP((B29-C29)/12*150*A29/12,0) -> 713 | F29: =ROUNDDOWN(C$4/$D29,1) -> 7.5 | G29: =4635/($D29-22*8) -> 8.6312849 | H29: =7250/(D29-22*8) -> 13.500931 | K29: L4 (59 psf capacity)
A30: 50 | B30: 25 | C30: 10 | D30: =ROUNDUP((B30-C30)/12*150*A30/12,0) -> 782 | F30: =ROUNDDOWN(C$4/$D30,1) -> 6.9 | G30: =4635/($D30-22*8) -> 7.6485149 | H30: =7250/(D30-22*8) -> 11.963696
A31: 48 | B31: 12.75 | C31: 10 | D31: =ROUNDUP((B31-C31)/12*150*A31/12,0) -> 138 | F31: =ROUNDDOWN(C$4/$D31,1) -> 39.1 | G31: =4635/($D31-22*8) -> -121.97368 | H31: =7250/(D31-22*8) -> -190.78947
A32: 48 | B32: 24 | C32: 10 | D32: =ROUNDUP((B32-C32)/12*150*A32/12,0) -> 700 | F32: =ROUNDDOWN(C$4/$D32,1) -> 7.7 | G32: =4635/($D32-22*8) -> 8.8454198 | H32: =7250/(D32-22*8) -> 13.835878 | L32: 155PSF-59PSF = 96PSF
A33: *Beam Load = (Beam Depth - Surrounding Slab Depth) / 12 x 150psf x (Beam Width / 12) | J33: 8'-6 1/2" SHORE HEIGHT | L33: 5400#/96PSF
L34: 56SF/SHORE
L35: 6X8 PATTERN
K37: L3 (59psf capacity)
L39: 96PSF-59PSF = 37PSF
J40: 8'-6 1/2" SHORE HEIGHT | L40: 5400#/37PSF
L41: 145SF/SHORE
L42: 10x10 PATTERN
K44: L2 (59 psf capacity)
J47: 10'-10 1/2" SHORE HEIGHT
K51: L1 SOG
J56: L4.5 12" Slab (180 psf)
J63: L4 (59 psf capacity)
K65: 180PSF-59PSF = 121PSF
I66: 8'-6 1/2" SHORE HEIGHT | K66: 5400#/141PSF
...

Sheet L4 Placement
A1: L3 Overview | E1: L4 TYPICAL SLAB LOADS
A2: Slab Capacity (psf)* = | B2: ='Floor Capacity Chart'!D9 -> 59 | C2: *#7 Per Floor Capacity Chart | E2: Slab Thickness (in) | F2: Construction DL (PSF) | G2: Total Load (psf)*
A3: Shore Height | B3: Shore Type | C3: Shore Capacity (lbs) | E3: 7.5 | F3: 30 | G3: =ROUNDUP(E3/12*150+F3,0) -> 124
A4: 8'-6 1/2" | B4: 6-6 Ellis Shore | C4: 5400 | E4: 9 | F4: 30 | G4: =ROUNDUP(E4/12*150+F4,0) -> 143
A5: 20'-1 1/2" | B5: HV 625 Shore | C5: 7300 | E5: *Total Load =(Slab Thickness / 12 x 150psf) + DL
F8: L4 7 1/2" Slab Placement Reshore (8'-6 1/2" Shore Height)
F9: Placement Load (psf) | G9: Reshore Level | H9: Reshore Level Capacity (psf) | I9: Resultant Floor Load | J9: Reshore Type | K9: Reshore Capacity | L9: SF/Shore | M9: Reshore Pattern | N9: Reshore Pattern 625
F10: =G3 -> 124 | G10: L3 | H10: =$B$2 -> 59 | I10: =F10-H10 -> 65 | J10: 6-6 Ellis Shore | K10: =C$4 -> 5400 | L10: =ROUNDDOWN(K10/I10,0) -> 83 | M10: =IF(AND(L10>24,L10<32),"4x6",IF(AND(L10>32,L10<36),"4x8",IF(AND(L10>36,L10<48),"6x6",IF(AND(L10>48,L10<60),"6x8",IF(AND(L10>60,L10<64),"6x10",IF(AND(L10>64,L10<80),"8x8",IF(AND(L10>80,L10<100),"8x10",IF(L10>100,"10x10","Not Needed")))))))) -> 8x10 | N10: 10x10
F11: =I10 -> 65 | G11: L2 | H11: 59 | I11: =F11-H11 -> 6 | J11: 6-8 Ellis Shore | K11: 4635 | L11: =ROUNDDOWN(K11/I11,0) -> 772 | M11: =IF(AND(L11>24,L11<32),"4x6",IF(AND(L11>32,L11<36),"4x8",IF(AND(L11>36,L11<48),"6x6",IF(AND(L11>48,L11<60),"6x8",IF(AND(L11>60,L11<64),"6x10",IF(AND(L11>64,L11<80),"8x8",IF(AND(L11>80,L11<100),"8x10",IF(L11>=100,"10x10","Not Needed")))))))) -> 10x10
G13: L4 7 1/2" Slab Placement Reshore (8'-6 1/2" Shore Height)
H15: L4 7 1/2" Slab (124 psf)
H22: L3 (59 psf capacity)
I24: 124PSF-59PSF = 65PSF
G25: 8'-6 1/2" SHORE HEIGHT | I25: 5400#/65PSF
I26: 83SF/SHORE
I27: 8x10 PATTERN
H29: L2 (59 psf capacity)
I31: 65PSF-59PSF = 6PSF
G32: 10'-10 1/2" SHORE HEIGHT | I32: 4635#/6PSF
I33: 772SF/SHORE
I34: 10X10 PATTERN
H36: L1 SOG
F66: L4 9" Slab Placement Reshore (8'-6 1/2" Shore Height)
F67: Placement Load (psf) | G67: Reshore Level | H67: Reshore Level Capacity (psf) | I67: Resultant Floor Load | J67: Reshore Type | K67: Reshore Capacity | L67: SF/Shore | M67: Reshore Pattern
F68: =G4 -> 143 | G68: L3 | H68: =$B$2 -> 59 | I68: =F68-H68 -> 84 | J68: 6-6 Ellis Shore | K68: =C$4 -> 5400 | L68: =ROUNDDOWN(K68/I68,0) -> 64 | M68: =IF(AND(L68>24,L68<32),"4x6",IF(AND(L68>32,L68<36),"4x8",IF(AND(L68>36,L68<48),"6x6",IF(AND(L68>48,L68<60),"6x8",IF(AND(L68>60,L68<64),"6x10",IF(AND(L68>=64,L68<80),"8x8",IF(AND(L68>80,L68<100),"8x10",IF(L68>100,"10x10","Not Needed")))))))) -> 8x8
F69: =I68 -> 84 | G69: L2 | H69: 59 | I69: =F69-H69 -> 25 | J69: 6-8 Ellis Shore | K69: 4635 | L69: =ROUNDDOWN(K69/I69,0) -> 185 | M69: =IF(AND(L69>24,L69<32),"4x6",IF(AND(L69>32,L69<36),"4x8",IF(AND(L69>36,L69<48),"6x6",IF(AND(L69>48,L69<60),"6x8",IF(AND(L69>60,L69<64),"6x10",IF(AND(L69>64,L69<80),"8x8",IF(AND(L69>80,L69<100),"8x10",IF(L69>=100,"10x10","Not Needed")))))))) -> 10x10
G71: L4 9" Slab Placement Reshore (8'-6 1/2" Shore Height)
H73: L4 9" Slab (143 psf)
H80: L3 (59 psf capacity)
I82: 143PSF-59PSF = 84PSF
G83: 8'-6 1/2" SHORE HEIGHT | I83: 5400#/84PSF
I84: 64SF/SHORE
I85: 8X8 PATTERN
H87: L2 (59 psf capacity)
I89: 104PSF-39PSF = 25PSF
G90: 10'-10 1/2" SHORE HEIGHT | I90: 4635#/25PSF
I91: 185SF/SHORE
I92: 10 PATTERN
H94: L1 SOG
F112: L4 7 1/2" Slab Placement Reshore (20'-0 1/2" Shore Height)
...

Sheet L4 Placement L3 0 Slab Capacity
A1: L3 Overview | E1: L4 TYPICAL SLAB LOADS
A2: Slab Capacity (psf)* = | B2: 0 | C2: *#7 Per Floor Capacity Chart | E2: Slab Thickness (in) | F2: Construction DL (PSF) | G2: Total Load (psf)*
A3: Shore Height | B3: Shore Type | C3: Shore Capacity (lbs) | E3: 7.5 | F3: 30 | G3: =ROUNDUP(E3/12*150+F3,0) -> 124
A4: 8'-6 1/2" | B4: 6-6 Ellis Shore | C4: 5400 | E4: 9 | F4: 30 | G4: =ROUNDUP(E4/12*150+F4,0) -> 143
A5: 20'-1 1/2" | B5: HV 625 Shore | C5: 7300 | E5: *Total Load =(Slab Thickness / 12 x 150psf) + DL
F8: L4 7 1/2" Slab Placement Reshore (8'-6 1/2" Shore Height)
F9: Placement Load (psf) | G9: Reshore Level | H9: Reshore Level Capacity (psf) | I9: Resultant Floor Load | J9: Reshore Type | K9: Reshore Capacity | L9: SF/Shore | M9: Reshore Pattern
F10: =G3 -> 124 | G10: L3 | H10: =$B$2 -> 0 | I10: =F10-H10 -> 124 | J10: 6-6 Ellis Shore | K10: =C$4 -> 5400 | L10: =ROUNDDOWN(K10/I10,0) -> 43 | M10: =IF(AND(L10>24,L10<32),"4x6",IF(AND(L10>32,L10<36),"4x8",IF(AND(L10>36,L10<48),"6x6",IF(AND(L10>48,L10<60),"6x8",IF(AND(L10>60,L10<64),"6x10",IF(AND(L10>64,L10<80),"8x8",IF(AND(L10>80,L10<100),"8x10",IF(L10>100,"10x10","Not Needed")))))))) -> 6x6
F11: =I10 -> 124 | G11: L2 | H11: 59 | I11: =F11-H11 -> 65 | J11: 6-8 Ellis Shore | K11: 4635 | L11: =ROUNDDOWN(K11/I11,0) -> 71 | M11: =IF(AND(L11>24,L11<32),"4x6",IF(AND(L11>32,L11<36),"4x8",IF(AND(L11>36,L11<48),"6x6",IF(AND(L11>48,L11<60),"6x8",IF(AND(L11>60,L11<64),"6x10",IF(AND(L11>64,L11<80),"8x8",IF(AND(L11>80,L11<100),"8x10",IF(L11>=100,"10x10","Not Needed")))))))) -> 8x8
G13: L4 7 1/2" Slab Placement Reshore (8'-6 1/2" Shore Height)
H15: L4 7 1/2" Slab (124 psf)
H22: L3 (0 psf capacity)
I24: 124PSF-0PSF = 124PSF
G25: 8'-6 1/2" SHORE HEIGHT | I25: 5400#/124PSF
I26: 43SF/SHORE
I27: 6X6 PATTERN
H29: L2 (59 psf capacity)
I31: 85PSF-59PSF = 65PSF
G32: 10'-10 1/2" SHORE HEIGHT | I32: 4635#/65PSF
I33: 71SF/SHORE
I34: 8x8 PATTERN
H36: L1 SOG

Sheet L3 Placement
A1: L2 Overview | E1: L3 TYPICAL SLAB LOADS
A2: Slab Capacity (psf)* = | B2: ='Floor Capacity Chart'!D9 -> 59 | C2: *#7 Per Floor Capacity Chart | E2: Slab Thickness (in) | F2: Construction DL (PSF) | G2: Total Load (psf)*
A3: Shore Height | B3: Shore Type | C3: Shore Capacity (lbs) | E3: 7.5 | F3: 30 | G3: =ROUNDUP(E3/12*150+F3,0) -> 124
A4: 10'-8 1/2" | B4: 6-8 Ellis Shore | C4: 4635 | E4: 9 | F4: 30 | G4: =ROUNDUP(E4/12*150+F4,0) -> 143
A5: 10'-10 1/2" | B5: 6-8 Ellis Shore | C5: 4635 | E5: *Total Load =(Slab Thickness / 12 x 150psf) + DL
A6: 14'-10 1/2" | B6: HV #5 Shore | C6: 7916
A7: 15'-3 1/2" | B7: HV #5 Shore | C7: 7500
G8: L3 7 1/2" Slab Placement Reshore (10'-8 1/2" - 10'-10 1/2" Shore Height)
G9: Placement Load (psf) | H9: Reshore Level | I9: Reshore Level Capacity (psf) | J9: Resultant Floor Load | K9: Reshore Type | L9: Reshore Capacity | M9: SF/Shore | N9: Reshore Pattern
G10: =$G$3 -> 124 | H10: L2 | I10: =$B$2 -> 59 | J10: =G10-I10 -> 65 | K10: 6-8 Ellis Shore | L10: =$C$5 -> 4635 | M10: =ROUNDDOWN(L10/J10,0) -> 71 | N10: =IF(AND(M10>24,M10<32),"4x6",IF(AND(M10>32,M10<36),"4x8",IF(AND(M10>36,M10<48),"6x6",IF(AND(M10>48,M10<60),"6x8",IF(AND(M10>60,M10<64),"6x10",IF(AND(M10>64,M10<80),"8x8",IF(AND(M10>80,M10<100),"8x10",IF(M10>100,"10x10","Not Needed")))))))) -> 8x8
H12: L3 7 1/2" Slab Placement Reshore (10'-8 1/2" - 10'-10 1/2" Shore Height)
I14: L3 7 1/2" Slab (124 psf)
I21: L2 (59 psf capacity)
J23: 124PSF-59PSF = 65PSF
H24: 10'-10 1/2" SHORE HEIGHT | J24: 4635#/65PSF
J25: 71SF/SHORE
J26: 8X8 PATTERN
I28: L1 SOG
G35: L3 7 1/2" Slab Placement Reshore (14'-10 1/2"- 15'-3 1/2" Shore Height)
G36: Placement Load (psf) | H36: Reshore Level | I36: Reshore Level Capacity (psf) | J36: Resultant Floor Load | K36: Reshore Type | L36: Reshore Capacity | M36: SF/Shore | N36: Reshore Pattern
G37: =G3 -> 124 | H37: L2 | I37: =$B$2 -> 59 | J37: =G37-I37 -> 65 | K37: HV #5 Shore | L37: 7500 | M37: =ROUNDDOWN(L37/J37,0) -> 115 | N37: =IF(AND(M37>24,M37<32),"4x6",IF(AND(M37>32,M37<36),"4x8",IF(AND(M37>36,M37<48),"6x6",IF(AND(M37>48,M37<60),"6x8",IF(AND(M37>60,M37<64),"6x10",IF(AND(M37>64,M37<80),"8x8",IF(AND(M37>80,M37<100),"8x10",IF(M37>100,"10x10","Not Needed")))))))) -> 10x10
H39: L3 7 1/2" Slab Placement Reshore (14'-10 1/2"- 15'-3 1/2" Shore Height)
I41: L3 7 1/2" Slab (124 psf)
I48: L2 (59 psf capacity)
J50: 124PSF-59PSF = 65PSF
H51: 15'-3 1/2" SHORE HEIGHT | J51: 7500#/65PSF
J52: 115SF/SHORE
J53: 10x10 PATTERN
I55: L1 SOG
L66: 1
G72: L3 9" Slab Placement Reshore (8'10" Shore Height)
G73: Placement Load (psf) | H73: Reshore Level | I73: Reshore Level Capacity (psf) | J73: Resultant Floor Load | K73: Reshore Type | L73: Reshore Capacity | M73: SF/Shore | N73: Reshore Pattern
G74: =G4 -> 143 | H74: L2 | I74: =$B$2 -> 59 | J74: =G74-I74 -> 84 | K74: HV #5 Shore | L74: 5400 | M74: =ROUNDDOWN(L74/J74,0) -> 64 | N74: =IF(AND(M74>24,M74<32),"4x6",IF(AND(M74>32,M74<36),"4x8",IF(AND(M74>36,M74<48),"6x6",IF(AND(M74>48,M74<60),"6x8",IF(AND(M74>60,M74<64),"6x10",IF(AND(M74>=64,M74<80),"8x8",IF(AND(M74>80,M74<100),"8x10",IF(M74>100,"10x10","Not Needed")))))))) -> 8x8
H76: L3 9" Slab Placement Reshore (14'-10 1/2"- 15'-3 1/2" Shore Height)
I78: L3 9" Slab (143 psf)
I85: L2 (59 psf capacity)
J87: 143PSF-59PSF = 84PSF
H88: 10'-10 1/2" SHORE HEIGHT | J88: 4635#/84PSF
J89: 55SF/SHORE
J90: 6x8 PATTERN
...

Sheet L3 Placement L2 0 Slab Capacity
A1: L2 Overview | E1: L3 TYPICAL SLAB LOADS
A2: Slab Capacity (psf)* = | B2: 0 | C2: *#7 Per Floor Capacity Chart | E2: Slab Thickness (in) | F2: Construction DL (PSF) | G2: Total Load (psf)*
A3: Shore Height | B3: Shore Type | C3: Shore Capacity (lbs) | E3: 7.5 | F3: 30 | G3: =ROUNDUP(E3/12*150+F3,0) -> 124
A4: 10'-8 1/2" | B4: 6-8 Ellis Shore | C4: 4635 | E4: 9 | F4: 30 | G4: =ROUNDUP(E4/12*150+F4,0) -> 143
A5: 10'-10 1/2" | B5: 6-8 Ellis Shore | C5: 4635 | E5: *Total Load =(Slab Thickness / 12 x 150psf) + DL
A6: 14'-10 1/2" | B6: HV #5 Shore | C6: 7916
A7: 15'-3 1/2" | B7: HV #5 Shore | C7: 7500
G8: L3 7 1/2" Slab Placement Reshore (10'-8 1/2" - 10'-10 1/2" Shore Height)
G9: Placement Load (psf) | H9: Reshore Level | I9: Reshore Level Capacity (psf) | J9: Resultant Floor Load | K9: Reshore Type | L9: Reshore Capacity | M9: SF/Shore | N9: Reshore Pattern
G10: =$G$3 -> 124 | H10: L2 | I10: =$B$2 -> 0 | J10: =G10-I10 -> 124 | K10: 6-8 Ellis Shore | L10: =$C$5 -> 4635 | M10: =ROUNDDOWN(L10/J10,0) -> 37 | N10: =IF(AND(M10>24,M10<32),"4x6",IF(AND(M10>32,M10<36),"4x8",IF(AND(M10>36,M10<48),"6x6",IF(AND(M10>48,M10<60),"6x8",IF(AND(M10>60,M10<64),"6x10",IF(AND(M10>64,M10<80),"8x8",IF(AND(M10>80,M10<100),"8x10",IF(M10>100,"10x10","Not Needed")))))))) -> 6x6
H12: L3 7 1/2" Slab Placement Reshore (10'-8 1/2" - 10'-10 1/2" Shore Height)
I14: L3 7 1/2" Slab (124 psf)
I21: L2 (0 psf capacity)
J23: 124PSF-39PSF = 124PSF
H24: 10'-10 1/2" SHORE HEIGHT | J24: 4635#/124PSF
J25: 37SF/SHORE
J26: 6X6 PATTERN
I28: L1 SOG
